<?xml version="1.0" encoding="utf-8"?>
<robot name="mowen" xmlns:xacro="http://wiki.ros.org/xacro">
    <material name="Green">
        <color rgba="0 0.7 0 1"/>
    </material>
    <material name="White">
        <color rgba="0.7 0.7 0.7 1"/>
    </material>

    <xacro:property name="ns" value="$(arg ns)"/>
    <link name="${ns}/base_footprint"/>

    <xacro:macro name="common_link" params="name material path *origin">
        <link name="${ns}/${name}">
            <visual>
                <geometry>
                    <mesh filename="package://robot_vs/config/mowen_param/meshes/${path}/${name}.STL"/>
                </geometry>
                <origin xyz="0 0 0" rpy="0 0 0"/>
                <material name="${material}"/>
            </visual>
            <collision>
                <geometry>
                    <mesh filename="package://robot_vs/config/mowen_param/meshes/${path}/${name}.STL"/>
                </geometry>
                <origin xyz="0 0 0" rpy="0 0 0"/>
            </collision>
            <xacro:insert_block name="origin"/>
        </link>
    </xacro:macro>
    <xacro:macro name="continuous_joint" params="name parent child xyz rpy axis">
        <joint name="${ns}/${name}" type="continuous">
            <parent link="${ns}/${parent}"/>
            <child link="${ns}/${child}"/>
            <origin xyz="${xyz}" rpy="${rpy}"/>
            <axis xyz="${axis}"/>
            <limit lower="${-pi}" upper="${pi}" effort="100" velocity="1"/>
        </joint>
    </xacro:macro>
    <xacro:macro name="fixed_joint" params="name parent child xyz rpy">
        <joint name="${ns}/${name}" type="fixed">
            <parent link="${ns}/${parent}"/>
            <child link="${ns}/${child}"/>
            <origin xyz="${xyz}" rpy="${rpy}"/>
        </joint>
    </xacro:macro>
    <common_link name="base_link" material="Green" path="mecanum">
        <inertial>
            <origin xyz="0.00498197982182523 5.70233829969297E-05 -0.0121008098068578" rpy="0 0 0"/>
            <mass value="0.486218814966626"/>
            <inertia
                    ixx="0.00196277727666921"
                    ixy="2.50447049446755E-07"
                    ixz="0.000140534767811098"
                    iyy="0.00457256033711368"
                    iyz="2.68618064993882E-07"
                    izz="0.00493927269870476"/>
        </inertial>
    </common_link>
    <fixed_joint name="base_joint" parent="base_footprint" child="base_link" xyz="0.0 0.0 0.0815" rpy="0 0 0"/>
</robot>